<?xml version="1.0" ?>
<!-- =================================================================================== -->
<!-- |    This document was autogenerated by xacro from /home/ubuntu/dev_ws/src/robot_arm_description/urdf/robotarm.urdf.xacro | -->
<!-- |    EDITING THIS FILE BY HAND IS NOT RECOMMENDED                                 | -->
<!-- =================================================================================== -->
<robot name="robot_arm">
  <!-- Links -->
  <link name="world"/>
  <link name="base_link">
    <inertial>
      <origin rpy="0 0 0" xyz="0 0 0"/>
      <mass value="1.0"/>
      <inertia ixx="1.0" ixy="0.0" ixz="0.0" iyy="1.0" iyz="0.0" izz="1.0"/>
    </inertial>
    <visual>
      <origin rpy="0 0 0" xyz="-0.5 -0.5 0"/>
      <geometry>
        <mesh filename="package://robot_arm_description/meshes/basement.STL" scale="0.01 0.01 0.01"/>
      </geometry>
    </visual>
    <collision>
      <origin rpy="0 0 0" xyz="-0.5 -0.5 0"/>
      <geometry>
        <mesh filename="package://robot_arm_description/meshes/basement.STL" scale="0.01 0.01 0.01"/>
      </geometry>
    </collision>
  </link>
  <link name="base_plate">
    <inertial>
      <origin rpy="0 0 0" xyz="0 0 0"/>
      <mass value="0.1"/>
      <inertia ixx="1.0" ixy="0.0" ixz="0.0" iyy="1.0" iyz="0.0" izz="1.0"/>
    </inertial>
    <visual>
      <origin rpy="0 0 0" xyz="-0.39 -0.39 -0.56"/>
      <geometry>
        <mesh filename="package://robot_arm_description/meshes/base_plate.STL" scale="0.01 0.01 0.01"/>
      </geometry>
    </visual>
    <collision>
      <origin rpy="0 0 0" xyz="-0.39 -0.39 -0.56"/>
      <geometry>
        <mesh filename="package://robot_arm_description/meshes/base_plate.STL" scale="0.01 0.01 0.01"/>
      </geometry>
    </collision>
  </link>
  <link name="forward_drive_arm">
    <inertial>
      <origin rpy="0 0 0" xyz="0 0 0"/>
      <mass value="0.1"/>
      <inertia ixx="1.0" ixy="0.0" ixz="0.0" iyy="1.0" iyz="0.0" izz="1.0"/>
    </inertial>
    <visual>
      <origin rpy=" 0 -1.570796326795 1.570796326795" xyz="0.19 0.06 -0.08"/>
      <geometry>
        <mesh filename="package://robot_arm_description/meshes/forward_drive_arm.STL" scale="0.01 0.01 0.01"/>
      </geometry>
    </visual>
    <collision>
      <origin rpy=" 0 -1.570796326795 1.570796326795" xyz="0.19 0.06 -0.08"/>
      <geometry>
        <mesh filename="package://robot_arm_description/meshes/forward_drive_arm.STL" scale="0.01 0.01 0.01"/>
      </geometry>
    </collision>
  </link>
  <link name="horizontal_arm">
    <inertial>
      <origin rpy="0 0 0" xyz="0 0 0"/>
      <mass value="0.1"/>
      <inertia ixx="1.0" ixy="0.0" ixz="0.0" iyy="1.0" iyz="0.0" izz="1.0"/>
    </inertial>
    <visual>
      <origin rpy="1.570796326795 0 1.570796326795" xyz="-0.03 -0.4 -0.06"/>
      <geometry>
        <mesh filename="package://robot_arm_description/meshes/horizontal_arm.STL" scale="0.01 0.01 0.01"/>
      </geometry>
    </visual>
    <collision>
      <origin rpy="1.570796326795 0 1.570796326795" xyz="-0.03 -0.4 -0.06"/>
      <geometry>
        <mesh filename="package://robot_arm_description/meshes/horizontal_arm.STL" scale="0.01 0.01 0.01"/>
      </geometry>
    </collision>
  </link>
  <link name="claw_support">
    <inertial>
      <origin rpy="0 0 0" xyz="0 0 0"/>
      <mass value="0.05"/>
      <inertia ixx="1.0" ixy="0.0" ixz="0.0" iyy="1.0" iyz="0.0" izz="1.0"/>
    </inertial>
    <visual>
      <origin rpy="0 0 1.570796326795" xyz="0 -0.05 -0.15"/>
      <geometry>
        <mesh filename="package://robot_arm_description/meshes/claw_support.STL" scale="0.01 0.01 0.01"/>
      </geometry>
    </visual>
    <collision>
      <origin rpy="0 0 1.570796326795" xyz="0 -0.05 -0.15"/>
      <geometry>
        <mesh filename="package://robot_arm_description/meshes/claw_support.STL" scale="0.01 0.01 0.01"/>
      </geometry>
    </collision>
  </link>
  <link name="gripper_right">
    <inertial>
      <origin rpy="0 0 0" xyz="0 0 0"/>
      <mass value="0.01"/>
      <inertia ixx="1.0" ixy="0.0" ixz="0.0" iyy="1.0" iyz="0.0" izz="1.0"/>
    </inertial>
    <visual>
      <origin rpy="0 0 -1.570796326795" xyz="-0.1 0.50 -0.1"/>
      <geometry>
        <mesh filename="package://robot_arm_description/meshes/right_finger.STL" scale="0.01 0.01 0.01"/>
      </geometry>
    </visual>
    <collision>
      <origin rpy="0 0 -1.570796326795" xyz="-0.1 0.50 -0.1"/>
      <geometry>
        <mesh filename="package://robot_arm_description/meshes/right_finger.STL" scale="0.01 0.01 0.01"/>
      </geometry>
    </collision>
  </link>
  <link name="gripper_left">
    <inertial>
      <origin rpy="0 0 0" xyz="0 0 0"/>
      <mass value="0.01"/>
      <inertia ixx="1.0" ixy="0.0" ixz="0.0" iyy="1.0" iyz="0.0" izz="1.0"/>
    </inertial>
    <visual>
      <origin rpy="0 0 -1.570796326795" xyz="-0.04 0.50 -0.1"/>
      <geometry>
        <mesh filename="package://robot_arm_description/meshes/left_finger.STL" scale="0.01 0.01 0.01"/>
      </geometry>
    </visual>
    <collision>
      <origin rpy="0 0 -1.570796326795" xyz="-0.04 0.50 -0.1"/>
      <geometry>
        <mesh filename="package://robot_arm_description/meshes/left_finger.STL" scale="0.01 0.01 0.01"/>
      </geometry>
    </collision>
  </link>
  <!-- Joints -->
  <joint name="virtual_joint" type="fixed">
    <parent link="world"/>
    <child link="base_link"/>
    <origin rpy="0 0 0" xyz="0 0 0"/>
  </joint>
  <joint name="joint_1" type="revolute">
    <parent link="base_link"/>
    <child link="base_plate"/>
    <origin xyz="0 0 0.307"/>
    <axis xyz="0 0 1"/>
    <limit effort="30.0" lower="-1.570796326795" upper="1.570796326795" velocity="10.0"/>
  </joint>
  <joint name="joint_2" type="revolute">
    <parent link="base_plate"/>
    <child link="forward_drive_arm"/>
    <origin xyz="-0.02 0 0.35"/>
    <axis xyz="1 0 0"/>
    <limit effort="30.0" lower="-1.570796326795" upper="1.570796326795" velocity="10.0"/>
  </joint>
  <joint name="joint_3" type="revolute">
    <parent link="forward_drive_arm"/>
    <child link="horizontal_arm"/>
    <origin xyz="0 0 0.8"/>
    <axis xyz="1 0 0"/>
    <limit effort="30.0" lower="-1.570796326795" upper="1.570796326795" velocity="10.0"/>
  </joint>
  <joint name="horizontal_arm_to_claw_support" type="fixed">
    <parent link="horizontal_arm"/>
    <child link="claw_support"/>
    <origin xyz="0 0.82 0"/>
  </joint>
  <joint name="joint_4" type="revolute">
    <parent link="claw_support"/>
    <child link="gripper_right"/>
    <origin xyz="-0.04 0.13 -0.1"/>
    <axis xyz="0 0 1"/>
    <limit effort="30.0" lower="-1.570796326795" upper="0.0" velocity="10.0"/>
  </joint>
  <joint name="joint_5" type="revolute">
    <parent link="claw_support"/>
    <child link="gripper_left"/>
    <origin xyz="-0.22 0.13 -0.1"/>
    <axis xyz="0 0 1"/>
    <limit effort="30.0" lower="0.0" upper="1.570796326795" velocity="10.0"/>
    <mimic joint="joint_4" multiplier="-1"/>
  </joint>
</robot>